Workbook

Sheet Сегодня
B2: ОПЕРАТИВНЫЙ ОТЧЁТ
B3: =Данные!E27&" "&Данные!C3 -> Апрель 2026 | J3: Дата: | K3: =Данные!C2 -> 46126
B6: KPI | H6: Выполнение плана | M6: Динамика по дням
C7: День | F7: Месяц | M7: date | N7: Чистая выручка | O7: Валовая прибыль | P7: Покупок
H8: =E9/K8 -> 0.48031757 | K8: =GETPIVOTDATA("[Measures].[Сумма по столбцу plan_amount]",Данные!$H$13) -> 14118466 | M8: 46113 | N8: 477417.99 | O8: 274303.94 | P8: 306
B9: =Данные!H4 -> 456149.43 | E9: {=public_mart_mtd_pulse[mtd_revenue]} -> 6781347.2 | K9: План | M9: 46114 | N9: 457417.23 | O9: 267560.88 | P9: 276
B10: =Данные!H4-Данные!H5 -> -55490.91 | E10: {=public_mart_mtd_pulse[mtd_revenue]-public_mart_mtd_pulse[prev_mtd_revenue]} -> -5731.86 | M10: 46115 | N10: 540786.09 | O10: 313030.34 | P10: 332
B11: Выручка | C11: =Данные!H4/Данные!H5-1 -> -0.10845687 | E11: Выручка | F11: {=public_mart_mtd_pulse[mtd_revenue]/public_mart_mtd_pulse[prev_mtd_revenue]-1} -> -0.0008445253 | M11: 46116 | N11: 527045.55 | O11: 284616.9 | P11: 310
H12: =E9/Данные!C5*Данные!C6 -> 14531458 | M12: 46117 | N12: 473509.46 | O12: 264130.76 | P12: 303
B13: =Данные!I4 -> 434 | E13: {=public_mart_mtd_pulse[mtd_orders]} -> 4234 | H13: =H12/K8 -> 1.0292519 | M13: 46118 | N13: 480800.75 | O13: 272374.1 | P13: 301
B14: =Данные!I4-Данные!I5 -> -33 | E14: {=public_mart_mtd_pulse[mtd_orders]-public_mart_mtd_pulse[prev_mtd_orders]} -> 108 | H14: Прогноз закрытия месяца | M14: 46119 | N14: 565194.02 | O14: 317143.12 | P14: 324
B15: Покупок | C15: =Данные!I4/Данные!I5-1 -> -0.070663812 | E15: Покупок | F15: {=public_mart_mtd_pulse[mtd_orders]/public_mart_mtd_pulse[prev_mtd_orders]-1} -> 0.026175473 | M15: 46120 | N15: 481399.15 | O15: 269888.3 | P15: 297
M16: 46121 | N16: 452385.45 | O16: 255173.65 | P16: 322
B17: =Данные!J4 -> 1051.04 | E17: {=public_mart_mtd_pulse[mtd_avg_order_value]} -> 1601.64 | H17: Разбивка по форматам | M17: 46122 | N17: 435220.77 | O17: 243035.12 | P17: 279
B18: =Данные!J4-Данные!J5 -> -44.55 | E18: {=public_mart_mtd_pulse[mtd_avg_order_value]-public_mart_mtd_pulse[prev_mtd_avg_order_value]} -> -43.31 | H18: Формат | I18: Факт | J18: План | K18: Выполнение | M18: 46123 | N18: 487648.31 | O18: 265837.71 | P18: 283
B19: Средний чек | C19: =Данные!J4/Данные!J5-1 -> -0.040663022 | E19: Средний чек | F19: {=public_mart_mtd_pulse[mtd_avg_order_value]/public_mart_mtd_pulse[prev_mtd_avg_order_value]-1} -> -0.026329068 | H19: Audiobook | I19: 3385419.5 | J19: 7128427.4 | K19: =GETPIVOTDATA("[Measures].[Сумма по столбцу fact_amount]",$H$18,"[public mart_plan_fact].[format]","[public mart_plan_fact].[format].&[Audiobook]")/GETPIVOTDATA("[Measures].[Сумма по столбцу plan_amount]",$H$18,"[public mart_plan_fact].[format]","[public mart_plan_fact].[format].&[Audiobook]") -> 0.47491815 | M19: 46124 | N19: 434732.65 | O19: 244450.05 | P19: 292
H20: eBook | I20: 327 | J20: 3658.98 | K20: =GETPIVOTDATA("[Measures].[Сумма по столбцу fact_amount]",$H$18,"[public mart_plan_fact].[format]","[public mart_plan_fact].[format].&[eBook]")/GETPIVOTDATA("[Measures].[Сумма по столбцу plan_amount]",$H$18,"[public mart_plan_fact].[format]","[public mart_plan_fact].[format].&[eBook]") -> 0.089369168 | M20: 46125 | N20: 511640.34 | O20: 281654.94 | P20: 317
B21: =Данные!K4 -> 255547.83 | E21: {=public_mart_mtd_pulse[mtd_gross_profit]} -> 3808747.6 | H21: Hardcover | I21: 2673599.3 | J21: 6395943.5 | K21: =GETPIVOTDATA("[Measures].[Сумма по столбцу fact_amount]",$H$18,"[public mart_plan_fact].[format]","[public mart_plan_fact].[format].&[Hardcover]")/GETPIVOTDATA("[Measures].[Сумма по столбцу plan_amount]",$H$18,"[public mart_plan_fact].[format]","[public mart_plan_fact].[format].&[Hardcover]") -> 0.41801484 | M21: 46126 | N21: 456149.43 | O21: 255547.83 | P21: 292
B22: =Данные!K4-Данные!K5 -> -26107.11 | E22: {=public_mart_mtd_pulse[mtd_gross_profit]-public_mart_mtd_pulse[prev_mtd_gross_profit]} -> 11320.94 | H22: Paperback | I22: 238812.33 | J22: 590435.9 | K22: =GETPIVOTDATA("[Measures].[Сумма по столбцу fact_amount]",$H$18,"[public mart_plan_fact].[format]","[public mart_plan_fact].[format].&[Paperback]")/GETPIVOTDATA("[Measures].[Сумма по столбцу plan_amount]",$H$18,"[public mart_plan_fact].[format]","[public mart_plan_fact].[format].&[Paperback]") -> 0.40446783
B23: Валовая прибыль | C23: =Данные!K4/Данные!K5-1 -> -0.092691824 | E23: Валовая прибыль | F23: {=public_mart_mtd_pulse[mtd_gross_profit]/public_mart_mtd_pulse[prev_mtd_gross_profit]-1} -> 0.0029812136
B25: =Данные!L4 -> 0.5602 | E25: {=public_mart_mtd_pulse[mtd_gross_margin]} -> 0.5617 | H25: Разбивка по жанрам
B26: =Данные!L4-Данные!L5 -> 0.0097 | E26: {=public_mart_mtd_pulse[mtd_gross_margin]-public_mart_mtd_pulse[prev_mtd_gross_margin]} -> 0.0022 | H26: Жанр | I26: Факт | J26: План | K26: Выполнение
B27: Валовая маржа | E27: Валовая маржа | H27: Biography | I27: 570899.41 | J27: 1180062.5 | K27: =GETPIVOTDATA("[Measures].[Сумма по столбцу fact_amount]",$H$26,"[public mart_plan_fact].[genre]","[public mart_plan_fact].[genre].&[Biography]")/GETPIVOTDATA("[Measures].[Сумма по столбцу plan_amount]",$H$26,"[public mart_plan_fact].[genre]","[public mart_plan_fact].[genre].&[Biography]") -> 0.48378743
H28: Business | I28: 387079.23 | J28: 857437.08 | K28: =GETPIVOTDATA("[Measures].[Сумма по столбцу fact_amount]",$H$26,"[public mart_plan_fact].[genre]","[public mart_plan_fact].[genre].&[Business]")/GETPIVOTDATA("[Measures].[Сумма по столбцу plan_amount]",$H$26,"[public mart_plan_fact].[genre]","[public mart_plan_fact].[genre].&[Business]") -> 0.45143747
H29: Children | I29: 835334.01 | J29: 1863203.4 | K29: =GETPIVOTDATA("[Measures].[Сумма по столбцу fact_amount]",$H$26,"[public mart_plan_fact].[genre]","[public mart_plan_fact].[genre].&[Children]")/GETPIVOTDATA("[Measures].[Сумма по столбцу plan_amount]",$H$26,"[public mart_plan_fact].[genre]","[public mart_plan_fact].[genre].&[Children]") -> 0.44833215
B30: Топ-5 товаров дня | H30: Fantasy | I30: 740545.76 | J30: 1708479.7 | K30: =GETPIVOTDATA("[Measures].[Сумма по столбцу fact_amount]",$H$26,"[public mart_plan_fact].[genre]","[public mart_plan_fact].[genre].&[Fantasy]")/GETPIVOTDATA("[Measures].[Сумма по столбцу plan_amount]",$H$26,"[public mart_plan_fact].[genre]","[public mart_plan_fact].[genre].&[Fantasy]") -> 0.43345307
B31: ID | C31: Название | D31: Формат | E31: Выручка | F31: Ранг | H31: Fiction | I31: 589200.25 | J31: 1335500.7 | K31: =GETPIVOTDATA("[Measures].[Сумма по столбцу fact_amount]",$H$26,"[public mart_plan_fact].[genre]","[public mart_plan_fact].[genre].&[Fiction]")/GETPIVOTDATA("[Measures].[Сумма по столбцу plan_amount]",$H$26,"[public mart_plan_fact].[genre]","[public mart_plan_fact].[genre].&[Fiction]") -> 0.44118304
B32: 952 | C32: Annual Subscription | D32: Subscription | E32: 19950 | F32: 1 | H32: History | I32: 479000.99 | J32: 1072568 | K32: =GETPIVOTDATA("[Measures].[Сумма по столбцу fact_amount]",$H$26,"[public mart_plan_fact].[genre]","[public mart_plan_fact].[genre].&[History]")/GETPIVOTDATA("[Measures].[Сумма по столбцу plan_amount]",$H$26,"[public mart_plan_fact].[genre]","[public mart_plan_fact].[genre].&[History]") -> 0.44659266
B33: 789 | C33: Падаль конструкция (History) | D33: Hardcover | E33: 9796 | F33: 2 | H33: Mystery | I33: 597056.37 | J33: 1385769.7 | K33: =GETPIVOTDATA("[Measures].[Сумма по столбцу fact_amount]",$H$26,"[public mart_plan_fact].[genre]","[public mart_plan_fact].[genre].&[Mystery]")/GETPIVOTDATA("[Measures].[Сумма по столбцу plan_amount]",$H$26,"[public mart_plan_fact].[genre]","[public mart_plan_fact].[genre].&[Mystery]") -> 0.4308482
B34: 888 | C34: Пастух ночь тысяча (Science) | D34: Audiobook | E34: 8838.08 | F34: 3 | H34: Poetry | I34: 667693.18 | J34: 1571101.2 | K34: =GETPIVOTDATA("[Measures].[Сумма по столбцу fact_amount]",$H$26,"[public mart_plan_fact].[genre]","[public mart_plan_fact].[genre].&[Poetry]")/GETPIVOTDATA("[Measures].[Сумма по столбцу plan_amount]",$H$26,"[public mart_plan_fact].[genre]","[public mart_plan_fact].[genre].&[Poetry]") -> 0.42498418
B35: 749 | C35: Нож скользить (Science) | D35: Hardcover | E35: 8365 | F35: 4 | H35: Romance | I35: 728848.48 | J35: 1714514.2 | K35: =GETPIVOTDATA("[Measures].[Сумма по столбцу fact_amount]",$H$26,"[public mart_plan_fact].[genre]","[public mart_plan_fact].[genre].&[Romance]")/GETPIVOTDATA("[Measures].[Сумма по столбцу plan_amount]",$H$26,"[public mart_plan_fact].[genre]","[public mart_plan_fact].[genre].&[Romance]") -> 0.42510495
B36: 755 | C36: Роскошный добиться (Mystery) | D36: Hardcover | E36: 7413 | F36: 5 | H36: Science | I36: 702500.51 | J36: 1429829.3 | K36: =GETPIVOTDATA("[Measures].[Сумма по столбцу fact_amount]",$H$26,"[public mart_plan_fact].[genre]","[public mart_plan_fact].[genre].&[Science]")/GETPIVOTDATA("[Measures].[Сумма по столбцу plan_amount]",$H$26,"[public mart_plan_fact].[genre]","[public mart_plan_fact].[genre].&[Science]") -> 0.49131774
B38: Low-stock виджет
B39: product_id | C39: title | D39: format | E39: genre | F39: publisher | G39: closing_stock | H39: is_low_stock | I39: stock_date | J39: avg_daily_sales_30d | K39: days_until_stockout | L39: recommended_order_qty | M39: alert_level

Sheet Данные
B2: Дата | C2: =F4 -> 46126 | E2: public_mart_daily_pulse
B3: Год | C3: =YEAR(C2) -> 2026 | E3: day_type | F3: report_date | G3: prev_date | H3: total_revenue | I3: total_orders | J3: avg_order_value | K3: total_gross_profit | L3: gross_margin
B4: Месяц | C4: =MONTH(C2) -> 4 | E4: today | F4: 46126 | G4: 46125 | H4: 456149.43 | I4: 434 | J4: 1051.04 | K4: 255547.83 | L4: 0.5602
B5: День | C5: =DAY(C2) -> 14 | E5: yesterday | F5: 46125 | G5: 46124 | H5: 511640.34 | I5: 467 | J5: 1095.59 | K5: 281654.94 | L5: 0.5505
B6: Всего дней | C6: =COUNT(C8:C38) -> 30
B8: Дни месяца | C8: {=DATE(C3,C4,1)+_xlfn.SEQUENCE(DAY(EOMONTH(DATE(C3,C4,1),0)),,0)} -> 46113 | E8: public_mart_mtd_pulse
C9: 46114 | E9: month_start | F9: month_to_date | G9: mtd_revenue | H9: mtd_orders | I9: mtd_net_qty | J9: mtd_gross_profit | K9: mtd_gross_margin | L9: prev_mtd_revenue | M9: prev_mtd_orders | N9: prev_mtd_net_qty | O9: prev_mtd_gross_profit | P9: prev_mtd_gross_margin | Q9: mtd_avg_order_value | R9: prev_mtd_avg_order_value
C10: 46115 | E10: 46113 | F10: 46126 | G10: 6781347.2 | H10: 4234 | I10: 9446 | J10: 3808747.6 | K10: 0.5617 | L10: 6787079 | M10: 4126 | N10: 9242 | O10: 3797426.7 | P10: 0.5595 | Q10: 1601.64 | R10: 1644.95
C11: 46116
C12: 46117 | E12: Месяцы
C13: 46118 | E13: 1 | F13: Январь | H13: План
C14: 46119 | E14: 2 | F14: Февраль | H14: 14118466
C15: 46120 | E15: 3 | F15: Март
C16: 46121 | E16: 4 | F16: Апрель
C17: 46122 | E17: 5 | F17: Май
C18: 46123 | E18: 6 | F18: Июнь
C19: 46124 | E19: 7 | F19: Июль
C20: 46125 | E20: 8 | F20: Август
C21: 46126 | E21: 9 | F21: Сентябрь
C22: 46127 | E22: 10 | F22: Октябрь
C23: 46128 | E23: 11 | F23: Ноябрь
C24: 46129 | E24: 12 | F24: Декабрь
C25: 46130
C26: 46131 | E26: Текущий месяц
C27: 46132 | E27: =VLOOKUP(C4,E13:F24,2,0) -> Апрель
C28: 46133
C29: 46134
C30: 46135
C31: 46136
C32: 46137
C33: 46138
C34: 46139
C35: 46140
C36: 46141
C37: 46142

Sheet История
B3: Выручка по месяцам
B4: Год | C4: Покупки | D4: Выручка | E4: Возвраты | F4: Чистая выручка | G4: Валовая прибыль | H4: Валовая маржа
B5: 2024 | C5: 139500 | D5: 1.5408472e+08 | E5: 1846146.5 | F5: 1.5223857e+08 | G5: 84021016 | H5: 0.50422476
B6: 2025 | C6: 155213 | D6: 1.7263498e+08 | E6: 1934468.1 | F6: 1.7070051e+08 | G6: 94066609 | H6: 0.50476916
B7: 2026 | C7: 42530 | D7: 47033670 | E7: 571872.05 | F7: 46461798 | G7: 25789651 | H7: 0.50800868
B8: Квартал1 | C8: 36301 | D8: 40186193 | E8: 505742.47 | F8: 39680451 | G8: 21980903 | H8: 0.51011303
B9: янв | C9: 10789 | D9: 11909371 | E9: 136469.19 | F9: 11772902 | G9: 6522617.8 | H9: 0.50801818
B10: фев | C10: 11840 | D10: 13020591 | E10: 182324.67 | F10: 12838266 | G10: 7107871.2 | H10: 0.50467051
B11: мар | C11: 13672 | D11: 15256232 | E11: 186948.61 | F11: 15069283 | G11: 8350414.4 | H11: 0.51717108
B12: Квартал2 | C12: 6229 | D12: 6847476.8 | E12: 66129.58 | F12: 6781347.2 | G12: 3808747.6 | H12: 0.50114795
B13: апр | C13: 6229 | D13: 6847476.8 | E13: 66129.58 | F13: 6781347.2 | G13: 3808747.6 | H13: 0.50114795
B14: Общий итог | C14: 337243 | D14: 3.7375337e+08 | E14: 4352486.7 | F14: 3.6940088e+08 | G14: 2.0387728e+08 | H14: 0.50500106
B17: Выполнение плана по месяцам
B18: Год | C18: Факт | D18: План | E18: Выполнение
B19: 2024 | C19: 1.4316596e+08 | D19: 1.5347972e+08 | E19: =GETPIVOTDATA("[Measures].[Сумма по столбцу fact_amount 2]",$B$18,"[public mart_plan_fact_history].[year]","[public mart_plan_fact_history].[year].&[2024]")/GETPIVOTDATA("[Measures].[Сумма по столбцу plan_amount 2]",$B$18,"[public mart_plan_fact_history].[year]","[public mart_plan_fact_history].[year].&[2024]") -> 0.93280049
B20: 1 | C20: 8824313.3 | D20: 9183936.5 | E20: =GETPIVOTDATA("[Measures].[Сумма по столбцу fact_amount 2]",$B$18,"[public mart_plan_fact_history].[year]","[public mart_plan_fact_history].[year].&[2024]","[public mart_plan_fact_history].[month]","[public mart_plan_fact_history].[month].&[1]")/GETPIVOTDATA("[Measures].[Сумма по столбцу plan_amount 2]",$B$18,"[public mart_plan_fact_history].[year]","[public mart_plan_fact_history].[year].&[2024]","[public mart_plan_fact_history].[month]","[public mart_plan_fact_history].[month].&[1]") -> 0.96084215
B21: 2 | C21: 10086983 | D21: 11290312 | E21: =GETPIVOTDATA("[Measures].[Сумма по столбцу fact_amount 2]",$B$18,"[public mart_plan_fact_history].[year]","[public mart_plan_fact_history].[year].&[2024]","[public mart_plan_fact_history].[month]","[public mart_plan_fact_history].[month].&[2]")/GETPIVOTDATA("[Measures].[Сумма по столбцу plan_amount 2]",$B$18,"[public mart_plan_fact_history].[year]","[public mart_plan_fact_history].[year].&[2024]","[public mart_plan_fact_history].[month]","[public mart_plan_fact_history].[month].&[2]") -> 0.89341938
B22: 3 | C22: 11195663 | D22: 12197593 | E22: =GETPIVOTDATA("[Measures].[Сумма по столбцу fact_amount 2]",$B$18,"[public mart_plan_fact_history].[year]","[public mart_plan_fact_history].[year].&[2024]","[public mart_plan_fact_history].[month]","[public mart_plan_fact_history].[month].&[3]")/GETPIVOTDATA("[Measures].[Сумма по столбцу plan_amount 2]",$B$18,"[public mart_plan_fact_history].[year]","[public mart_plan_fact_history].[year].&[2024]","[public mart_plan_fact_history].[month]","[public mart_plan_fact_history].[month].&[3]") -> 0.91785839
B23: 4 | C23: 11427578 | D23: 12095543 | E23: =GETPIVOTDATA("[Measures].[Сумма по столбцу fact_amount 2]",$B$18,"[public mart_plan_fact_history].[year]","[public mart_plan_fact_history].[year].&[2024]","[public mart_plan_fact_history].[month]","[public mart_plan_fact_history].[month].&[4]")/GETPIVOTDATA("[Measures].[Сумма по столбцу plan_amount 2]",$B$18,"[public mart_plan_fact_history].[year]","[public mart_plan_fact_history].[year].&[2024]","[public mart_plan_fact_history].[month]","[public mart_plan_fact_history].[month].&[4]") -> 0.9447759
B24: 5 | C24: 11461300 | D24: 12316975 | E24: =GETPIVOTDATA("[Measures].[Сумма по столбцу fact_amount 2]",$B$18,"[public mart_plan_fact_history].[year]","[public mart_plan_fact_history].[year].&[2024]","[public mart_plan_fact_history].[month]","[public mart_plan_fact_history].[month].&[5]")/GETPIVOTDATA("[Measures].[Сумма по столбцу plan_amount 2]",$B$18,"[public mart_plan_fact_history].[year]","[public mart_plan_fact_history].[year].&[2024]","[public mart_plan_fact_history].[month]","[public mart_plan_fact_history].[month].&[5]") -> 0.93052876
B25: 6 | C25: 10964049 | D25: 11640054 | E25: =GETPIVOTDATA("[Measures].[Сумма по столбцу fact_amount 2]",$B$18,"[public mart_plan_fact_history].[year]","[public mart_plan_fact_history].[year].&[2024]","[public mart_plan_fact_history].[month]","[public mart_plan_fact_history].[month].&[6]")/GETPIVOTDATA("[Measures].[Сумма по столбцу plan_amount 2]",$B$18,"[public mart_plan_fact_history].[year]","[public mart_plan_fact_history].[year].&[2024]","[public mart_plan_fact_history].[month]","[public mart_plan_fact_history].[month].&[6]") -> 0.94192428
B26: 7 | C26: 7027217 | D26: 7558096.1 | E26: =GETPIVOTDATA("[Measures].[Сумма по столбцу fact_amount 2]",$B$18,"[public mart_plan_fact_history].[year]","[public mart_plan_fact_history].[year].&[2024]","[public mart_plan_fact_history].[month]","[public mart_plan_fact_history].[month].&[7]")/GETPIVOTDATA("[Measures].[Сумма по столбцу plan_amount 2]",$B$18,"[public mart_plan_fact_history].[year]","[public mart_plan_fact_history].[year].&[2024]","[public mart_plan_fact_history].[month]","[public mart_plan_fact_history].[month].&[7]") -> 0.9297602
B27: 8 | C27: 11545517 | D27: 12681288 | E27: =GETPIVOTDATA("[Measures].[Сумма по столбцу fact_amount 2]",$B$18,"[public mart_plan_fact_history].[year]","[public mart_plan_fact_history].[year].&[2024]","[public mart_plan_fact_history].[month]","[public mart_plan_fact_history].[month].&[8]")/GETPIVOTDATA("[Measures].[Сумма по столбцу plan_amount 2]",$B$18,"[public mart_plan_fact_history].[year]","[public mart_plan_fact_history].[year].&[2024]","[public mart_plan_fact_history].[month]","[public mart_plan_fact_history].[month].&[8]") -> 0.91043726
B28: 9 | C28: 15448377 | D28: 16215008 | E28: =GETPIVOTDATA("[Measures].[Сумма по столбцу fact_amount 2]",$B$18,"[public mart_plan_fact_history].[year]","[public mart_plan_fact_history].[year].&[2024]","[public mart_plan_fact_history].[month]","[public mart_plan_fact_history].[month].&[9]")/GETPIVOTDATA("[Measures].[Сумма по столбцу plan_amount 2]",$B$18,"[public mart_plan_fact_history].[year]","[public mart_plan_fact_history].[year].&[2024]","[public mart_plan_fact_history].[month]","[public mart_plan_fact_history].[month].&[9]") -> 0.95272092
B29: 10 | C29: 11188309 | D29: 11857691 | E29: =GETPIVOTDATA("[Measures].[Сумма по столбцу fact_amount 2]",$B$18,"[public mart_plan_fact_history].[year]","[public mart_plan_fact_history].[year].&[2024]","[public mart_plan_fact_history].[month]","[public mart_plan_fact_history].[month].&[10]")/GETPIVOTDATA("[Measures].[Сумма по столбцу plan_amount 2]",$B$18,"[public mart_plan_fact_history].[year]","[public mart_plan_fact_history].[year].&[2024]","[public mart_plan_fact_history].[month]","[public mart_plan_fact_history].[month].&[10]") -> 0.94354866
B30: 11 | C30: 11534874 | D30: 12664298 | E30: =GETPIVOTDATA("[Measures].[Сумма по столбцу fact_amount 2]",$B$18,"[public mart_plan_fact_history].[year]","[public mart_plan_fact_history].[year].&[2024]","[public mart_plan_fact_history].[month]","[public mart_plan_fact_history].[month].&[11]")/GETPIVOTDATA("[Measures].[Сумма по столбцу plan_amount 2]",$B$18,"[public mart_plan_fact_history].[year]","[public mart_plan_fact_history].[year].&[2024]","[public mart_plan_fact_history].[month]","[public mart_plan_fact_history].[month].&[11]") -> 0.91081828
B31: 12 | C31: 22461781 | D31: 23778929 | E31: =GETPIVOTDATA("[Measures].[Сумма по столбцу fact_amount 2]",$B$18,"[public mart_plan_fact_history].[year]","[public mart_plan_fact_history].[year].&[2024]","[public mart_plan_fact_history].[month]","[public mart_plan_fact_history].[month].&[12]")/GETPIVOTDATA("[Measures].[Сумма по столбцу plan_amount 2]",$B$18,"[public mart_plan_fact_history].[year]","[public mart_plan_fact_history].[year].&[2024]","[public mart_plan_fact_history].[month]","[public mart_plan_fact_history].[month].&[12]") -> 0.9446086
B32: 2025 | C32: 1.5868874e+08 | D32: 1.6162181e+08 | E32: =GETPIVOTDATA("[Measures].[Сумма по столбцу fact_amount 2]",$B$18,"[public mart_plan_fact_history].[year]","[public mart_plan_fact_history].[year].&[2025]")/GETPIVOTDATA("[Measures].[Сумма по столбцу plan_amount 2]",$B$18,"[public mart_plan_fact_history].[year]","[public mart_plan_fact_history].[year].&[2025]") -> 0.98185227
B33: 1 | C33: 9957531.8 | D33: 9721279.2 | E33: =GETPIVOTDATA("[Measures].[Сумма по столбцу fact_amount 2]",$B$18,"[public mart_plan_fact_history].[year]","[public mart_plan_fact_history].[year].&[2025]","[public mart_plan_fact_history].[month]","[public mart_plan_fact_history].[month].&[1]")/GETPIVOTDATA("[Measures].[Сумма по столбцу plan_amount 2]",$B$18,"[public mart_plan_fact_history].[year]","[public mart_plan_fact_history].[year].&[2025]","[public mart_plan_fact_history].[month]","[public mart_plan_fact_history].[month].&[1]") -> 1.0243026
B34: 2 | C34: 11435412 | D34: 11829228 | E34: =GETPIVOTDATA("[Measures].[Сумма по столбцу fact_amount 2]",$B$18,"[public mart_plan_fact_history].[year]","[public mart_plan_fact_history].[year].&[2025]","[public mart_plan_fact_history].[month]","[public mart_plan_fact_history].[month].&[2]")/GETPIVOTDATA("[Measures].[Сумма по столбцу plan_amount 2]",$B$18,"[public mart_plan_fact_history].[year]","[public mart_plan_fact_history].[year].&[2025]","[public mart_plan_fact_history].[month]","[public mart_plan_fact_history].[month].&[2]") -> 0.96670824
B35: 3 | C35: 12822645 | D35: 13261072 | E35: =GETPIVOTDATA("[Measures].[Сумма по столбцу fact_amount 2]",$B$18,"[public mart_plan_fact_history].[year]","[public mart_plan_fact_history].[year].&[2025]","[public mart_plan_fact_history].[month]","[public mart_plan_fact_history].[month].&[3]")/GETPIVOTDATA("[Measures].[Сумма по столбцу plan_amount 2]",$B$18,"[public mart_plan_fact_history].[year]","[public mart_plan_fact_history].[year].&[2025]","[public mart_plan_fact_history].[month]","[public mart_plan_fact_history].[month].&[3]") -> 0.96693877
B36: 4 | C36: 11484016 | D36: 12367328 | E36: =GETPIVOTDATA("[Measures].[Сумма по столбцу fact_amount 2]",$B$18,"[public mart_plan_fact_history].[year]","[public mart_plan_fact_history].[year].&[2025]","[public mart_plan_fact_history].[month]","[public mart_plan_fact_history].[month].&[4]")/GETPIVOTDATA("[Measures].[Сумма по столбцу plan_amount 2]",$B$18,"[public mart_plan_fact_history].[year]","[public mart_plan_fact_history].[year].&[2025]","[public mart_plan_fact_history].[month]","[public mart_plan_fact_history].[month].&[4]") -> 0.92857704
B37: 5 | C37: 13271578 | D37: 12813526 | E37: =GETPIVOTDATA("[Measures].[Сумма по столбцу fact_amount 2]",$B$18,"[public mart_plan_fact_history].[year]","[public mart_plan_fact_history].[year].&[2025]","[public mart_plan_fact_history].[month]","[public mart_plan_fact_history].[month].&[5]")/GETPIVOTDATA("[Measures].[Сумма по столбцу plan_amount 2]",$B$18,"[public mart_plan_fact_history].[year]","[public mart_plan_fact_history].[year].&[2025]","[public mart_plan_fact_history].[month]","[public mart_plan_fact_history].[month].&[5]") -> 1.0357476
B38: 6 | C38: 12340209 | D38: 12353300 | E38: =GETPIVOTDATA("[Measures].[Сумма по столбцу fact_amount 2]",$B$18,"[public mart_plan_fact_history].[year]","[public mart_plan_fact_history].[year].&[2025]","[public mart_plan_fact_history].[month]","[public mart_plan_fact_history].[month].&[6]")/GETPIVOTDATA("[Measures].[Сумма по столбцу plan_amount 2]",$B$18,"[public mart_plan_fact_history].[year]","[public mart_plan_fact_history].[year].&[2025]","[public mart_plan_fact_history].[month]","[public mart_plan_fact_history].[month].&[6]") -> 0.99894035
B39: 7 | C39: 7732086.4 | D39: 7986631.8 | E39: =GETPIVOTDATA("[Measures].[Сумма по столбцу fact_amount 2]",$B$18,"[public mart_plan_fact_history].[year]","[public mart_plan_fact_history].[year].&[2025]","[public mart_plan_fact_history].[month]","[public mart_plan_fact_history].[month].&[7]")/GETPIVOTDATA("[Measures].[Сумма по столбцу plan_amount 2]",$B$18,"[public mart_plan_fact_history].[year]","[public mart_plan_fact_history].[year].&[2025]","[public mart_plan_fact_history].[month]","[public mart_plan_fact_history].[month].&[7]") -> 0.96812857
B40: 8 | C40: 12436169 | D40: 13451239 | E40: =GETPIVOTDATA("[Measures].[Сумма по столбцу fact_amount 2]",$B$18,"[public mart_plan_fact_history].[year]","[public mart_plan_fact_history].[year].&[2025]","[public mart_plan_fact_history].[month]","[public mart_plan_fact_history].[month].&[8]")/GETPIVOTDATA("[Measures].[Сумма по столбцу plan_amount 2]",$B$18,"[public mart_plan_fact_history].[year]","[public mart_plan_fact_history].[year].&[2025]","[public mart_plan_fact_history].[month]","[public mart_plan_fact_history].[month].&[8]") -> 0.92453706
B41: 9 | C41: 16992305 | D41: 17301906 | E41: =GETPIVOTDATA("[Measures].[Сумма по столбцу fact_amount 2]",$B$18,"[public mart_plan_fact_history].[year]","[public mart_plan_fact_history].[year].&[2025]","[public mart_plan_fact_history].[month]","[public mart_plan_fact_history].[month].&[9]")/GETPIVOTDATA("[Measures].[Сумма по столбцу plan_amount 2]",$B$18,"[public mart_plan_fact_history].[year]","[public mart_plan_fact_history].[year].&[2025]","[public mart_plan_fact_history].[month]","[public mart_plan_fact_history].[month].&[9]") -> 0.98210596
B42: 10 | C42: 13269239 | D42: 12968879 | E42: =GETPIVOTDATA("[Measures].[Сумма по столбцу fact_amount 2]",$B$18,"[public mart_plan_fact_history].[year]","[public mart_plan_fact_history].[year].&[2025]","[public mart_plan_fact_history].[month]","[public mart_plan_fact_history].[month].&[10]")/GETPIVOTDATA("[Measures].[Сумма по столбцу plan_amount 2]",$B$18,"[public mart_plan_fact_history].[year]","[public mart_plan_fact_history].[year].&[2025]","[public mart_plan_fact_history].[month]","[public mart_plan_fact_history].[month].&[10]") -> 1.0231601
B43: 11 | C43: 13337856 | D43: 13462760 | E43: =GETPIVOTDATA("[Measures].[Сумма по столбцу fact_amount 2]",$B$18,"[public mart_plan_fact_history].[year]","[public mart_plan_fact_history].[year].&[2025]","[public mart_plan_fact_history].[month]","[public mart_plan_fact_history].[month].&[11]")/GETPIVOTDATA("[Measures].[Сумма по столбцу plan_amount 2]",$B$18,"[public mart_plan_fact_history].[year]","[public mart_plan_fact_history].[year].&[2025]","[public mart_plan_fact_history].[month]","[public mart_plan_fact_history].[month].&[11]") -> 0.99072228
B44: 12 | C44: 23609689 | D44: 24104659 | E44: =GETPIVOTDATA("[Measures].[Сумма по столбцу fact_amount 2]",$B$18,"[public mart_plan_fact_history].[year]","[public mart_plan_fact_history].[year].&[2025]","[public mart_plan_fact_history].[month]","[public mart_plan_fact_history].[month].&[12]")/GETPIVOTDATA("[Measures].[Сумма по столбцу plan_amount 2]",$B$18,"[public mart_plan_fact_history].[year]","[public mart_plan_fact_history].[year].&[2025]","[public mart_plan_fact_history].[month]","[public mart_plan_fact_history].[month].&[12]") -> 0.9794658
...
